Workbook

Sheet Plan
J2: Return
F3: Started date | H3: 45566 | J3: Tabungan | K3: 0
F4: Inflasi | H4: 0.04 | J4: Rks. Pasar Uang | K4: 0.05
F5: Kenaikan properti | H5: 0.06 | J5: Rks. Obligasi | K5: 0.07
F6: Kenaikan kendaraan | H6: 0.08 | J6: Rks. Campuran | K6: 0.1
J7: Rks. Saham | K7: 0.12
AD8: 36129106
AD9: 14857848
C10: Updated Date | E10: 45778 | AD10: =AD8+AD9 -> 50986954
B11: Kode | C11: Goals | D11: Progress (N) | E11: Progress | F11: Time frame | G11: Started | H11: Date | I11: Months | J11: Nominal | K11: Future Value | L11: Present Value | M11: Product | N11: Payment | O11: 45566 | P11: 45597 | Q11: 45627 | R11: 45658 | S11: 45689 | T11: 45717 | U11: 45748 | V11: 45778 | W11: 45809 | X11: 45839 | Y11: 45870 | Z11: 45901 | AA11: Future Value | AB11: Selisih | AC11: Payment
B12: A1 | C12: Pindahan di Jogja | D12: =SUMIF(Process!$F$3:$F$204,Plan!B12,Process!$E$3:$E$204) -> 0 | E12: =IF(D12<1,100%,D12/K12) -> 1 | F12: Jangka Pendek (1,5 tahun / 2025 / 23) | G12: 45566 | H12: 45597 | I12: =(YEAR(H12)-YEAR(G12))*12+MONTH(H12)-MONTH(G12) -> 1 | J12: 750000 | K12: =-FV($H$4/12,I12,0,J12,0) -> 752500 | L12: 750000 | M12: Tabungan | N12: =ROUND(PMT((IF($M12=$J$3,$K$3,IF($M12=$J$4,$K$4,IF($M12=$J$5,$K$5,IF($M12=$J$6,$K$6,IF($M12=$J$7,$K$7)))))/12),I12,0,-K12,0),-2) -> 752500 | O12: 750000 | AA12: {=SUMPRODUCT(O12:Z12*(1 +(IF(M12=$J$3,$K$3,IF(M12=$J$4,$K$4,IF(M12=$J$5,$K$5,IF(M12=$J$6,$K$6,IF(M12=$J$7,$K$7)))))/12))^((COLUMN(O12:Z12) - COLUMN(O12))))} -> 750000 | AB12: =K12-AA12 -> 2500 | AC12: =ROUND(PMT((IF($M12=$J$3,$K$3,IF($M12=$J$4,$K$4,IF($M12=$J$5,$K$5,IF($M12=$J$6,$K$6,IF($M12=$J$7,$K$7)))))/12),(I12-12),0,-AB12,0),-2) -> -200
B13: A2 | C13: Balik Tegal | D13: =SUMIF(Process!$F$3:$F$204,Plan!B13,Process!$E$3:$E$204) -> -5236.533 | E13: =IF(D13<1,100%,D13/K13) -> 1 | F13: Jangka Pendek (1,5 tahun / 2025 / 23) | G13: 45566 | H13: 45597 | I13: =(YEAR(H13)-YEAR(G13))*12+MONTH(H13)-MONTH(G13) -> 1 | J13: 400000 | K13: =-FV($H$4/12,I13,0,J13,0) -> 401333.33 | L13: =K13/I13 -> 401333.33 | M13: Rks. Campuran | N13: =ROUND(PMT((IF(M13=$J$3,$K$3,IF(M13=$J$4,$K$4,IF(M13=$J$5,$K$5,IF(M13=$J$6,$K$6,IF(M13=$J$7,$K$7)))))/12),I13,0,-K13,0),-2) -> 401300 | O13: 400000 | AA13: {=SUMPRODUCT(O13:Z13*(1 +(IF(M13=$J$3,$K$3,IF(M13=$J$4,$K$4,IF(M13=$J$5,$K$5,IF(M13=$J$6,$K$6,IF(M13=$J$7,$K$7)))))/12))^((COLUMN(O13:Z13) - COLUMN(O13))))} -> 400000 | AB13: =K13-AA13 -> 1333.3333 | AC13: =ROUND(PMT((IF($M13=$J$3,$K$3,IF($M13=$J$4,$K$4,IF($M13=$J$5,$K$5,IF($M13=$J$6,$K$6,IF($M13=$J$7,$K$7)))))/12),(I13-12),0,-AB13,0),-2) -> -100
B14: A3 | C14: Wisuda (Fotografer, makeup, outfit, tiket bolak balik) | D14: =SUMIF(Process!$F$3:$F$204,Plan!B14,Process!$E$3:$E$204) -> 2.3283064e-09 | E14: =IF(D14<1,100%,D14/K14) -> 1 | F14: Jangka Pendek (1,5 tahun / 2025 / 23) | G14: 45566 | H14: 45689 | I14: =(YEAR(H14)-YEAR(G14))*12+MONTH(H14)-MONTH(G14) -> 4 | J14: 3000000 | K14: =-FV($H$4/12,I14,0,J14,0) -> 3040200.4 | L14: =K14/I14 -> 760050.11 | M14: Rks. Campuran | N14: =ROUND(PMT((IF(M14=$J$3,$K$3,IF(M14=$J$4,$K$4,IF(M14=$J$5,$K$5,IF(M14=$J$6,$K$6,IF(M14=$J$7,$K$7)))))/12),I14,0,-K14,0),-2) -> 750600 | O14: 505000 | P14: =O14 -> 505000 | Q14: 1000000 | R14: =Q14 -> 1000000 | AA14: {=SUMPRODUCT(O14:Z14*(1 +(IF(M14=$J$3,$K$3,IF(M14=$J$4,$K$4,IF(M14=$J$5,$K$5,IF(M14=$J$6,$K$6,IF(M14=$J$7,$K$7)))))/12))^((COLUMN(O14:Z14) - COLUMN(O14))))} -> 3056153.4 | AB14: =K14-AA14 -> -15952.912 | AC14: =ROUND(PMT((IF($M14=$J$3,$K$3,IF($M14=$J$4,$K$4,IF($M14=$J$5,$K$5,IF($M14=$J$6,$K$6,IF($M14=$J$7,$K$7)))))/12),(I14-12),0,-AB14,0),-2) -> 2100
B15: A4 | C15: Upgrade outfit kerja | D15: =SUMIF(Process!$F$3:$F$204,Plan!B15,Process!$E$3:$E$204) -> -19960.254 | E15: =IF(D15<1,100%,D15/K15) -> 1 | F15: Jangka Pendek (1,5 tahun / 2025 / 23) | G15: 45566 | H15: 45717 | I15: =(YEAR(H15)-YEAR(G15))*12+MONTH(H15)-MONTH(G15) -> 5 | J15: 2000000 | K15: =-FV($H$4/12,I15,0,J15,0) -> 2033556.3 | L15: =K15/I15 -> 406711.26 | M15: Rks. Obligasi | N15: =ROUND(PMT((IF(M15=$J$3,$K$3,IF(M15=$J$4,$K$4,IF(M15=$J$5,$K$5,IF(M15=$J$6,$K$6,IF(M15=$J$7,$K$7)))))/12),I15,0,-K15,0),-2) -> 402000 | O15: 405000 | P15: =O15 -> 405000 | Q15: =P15 -> 405000 | R15: =Q15 -> 405000 | S15: =R15 -> 405000 | AA15: {=SUMPRODUCT(O15:Z15*(1 +(IF(M15=$J$3,$K$3,IF(M15=$J$4,$K$4,IF(M15=$J$5,$K$5,IF(M15=$J$6,$K$6,IF(M15=$J$7,$K$7)))))/12))^((COLUMN(O15:Z15) - COLUMN(O15))))} -> 2048763.2 | AB15: =K15-AA15 -> -15206.917 | AC15: =ROUND(PMT((IF($M15=$J$3,$K$3,IF($M15=$J$4,$K$4,IF($M15=$J$5,$K$5,IF($M15=$J$6,$K$6,IF($M15=$J$7,$K$7)))))/12),(I15-12),0,-AB15,0),-2) -> 2200
B16: A5 | C16: Self Reward (Upgrade HP / Liburan) | D16: =SUMIF(Process!$F$3:$F$204,Plan!B16,Process!$E$3:$E$204) -> 3257918.2 | E16: =IF(D16<1,100%,D16/K16) -> 0.70261998 | F16: Jangka Pendek (1,5 tahun / 2025 / 23) | G16: 45566 | H16: 45839 | I16: =(YEAR(H16)-YEAR(G16))*12+MONTH(H16)-MONTH(G16) -> 9 | J16: 4500000 | K16: =-FV($H$4/12,I16,0,J16,0) -> 4636814.1 | L16: =K16/I16 -> 515201.56 | M16: Rks. Campuran | N16: =ROUND(PMT((IF(M16=$J$3,$K$3,IF(M16=$J$4,$K$4,IF(M16=$J$5,$K$5,IF(M16=$J$6,$K$6,IF(M16=$J$7,$K$7)))))/12),I16,0,-K16,0),-2) -> 498300 | O16: 450000 | P16: =O16 -> 450000 | Q16: =P16 -> 450000 | R16: =Q16 -> 450000 | S16: =R16 -> 450000 | T16: =S16 -> 450000 | U16: 600000 | V16: =U16 -> 600000 | W16: =V16 -> 600000 | AA16: {=SUMPRODUCT(O16:Z16*(1 +(IF(M16=$J$3,$K$3,IF(M16=$J$4,$K$4,IF(M16=$J$5,$K$5,IF(M16=$J$6,$K$6,IF(M16=$J$7,$K$7)))))/12))^((COLUMN(O16:Z16) - COLUMN(O16))))} -> 4664584.5 | AB16: =K16-AA16 -> -27770.407 | AC16: =ROUND(PMT((IF($M16=$J$3,$K$3,IF($M16=$J$4,$K$4,IF($M16=$J$5,$K$5,IF($M16=$J$6,$K$6,IF($M16=$J$7,$K$7)))))/12),(I16-12),0,-AB16,0),-2) -> 9400
B17: A6 | C17: Zakat | D17: =SUMIF(Process!$F$3:$F$204,Plan!B17,Process!$E$3:$E$204) -> 0 | E17: =IF(D17<1,100%,D17/K17) -> 1 | F17: Jangka Pendek (1,5 tahun / 2025 / 23) | G17: 45778 | H17: 46143 | I17: =(YEAR(H17)-YEAR(G17))*12+MONTH(H17)-MONTH(G17) -> 12 | J17: =250000*I17 -> 3000000 | K17: 3000000 | M17: Rks. Pasar Uang | N17: =K17/I17 -> 250000 | W17: 250000 | X17: 250000 | Y17: 250000 | Z17: 0
B18: B1 | C18: Dana Darurat | D18: =SUMIF(Process!$F$3:$F$204,Plan!B18,Process!$E$3:$E$204) -> 6078681.2 | E18: =IF(D18<1,100%,D18/K18) -> 0.38168384 | F18: Jangka Menengah (5 tahun / 2029 / 27) | G18: 45566 | H18: 46113 | I18: =(YEAR(H18)-YEAR(G18))*12+MONTH(H18)-MONTH(G18) -> 18 | J18: 15000000 | K18: =-FV($H$4/12,I18,0,J18,0) -> 15925959 | L18: =K18/I18 -> 884775.5 | M18: Rks. Pasar Uang | N18: =ROUND(PMT((IF(M18=$J$3,$K$3,IF(M18=$J$4,$K$4,IF(M18=$J$5,$K$5,IF(M18=$J$6,$K$6,IF(M18=$J$7,$K$7)))))/12),I18,0,-K18,0),-2) -> 853900 | O18: 880000 | P18: =O18 -> 880000 | Q18: =P18 -> 880000 | R18: =Q18 -> 880000 | S18: =R18 -> 880000 | T18: =S18 -> 880000 | U18: =T18 -> 880000 | V18: =U18 -> 880000 | W18: =V18 -> 880000 | ... Y18: =X18 -> 880000 | Z18: 0 | AA18: {=SUMPRODUCT(O18:Z18*(1 +(IF(M18=$J$3,$K$3,IF(M18=$J$4,$K$4,IF(M18=$J$5,$K$5,IF(M18=$J$6,$K$6,IF(M18=$J$7,$K$7)))))/12))^((COLUMN(O18:Z18) - COLUMN(O18))))} -> 9884208.6 | AB18: =K18-AA18 -> 6041750.4 | AC18: =ROUND(PMT((IF($M18=$J$3,$K$3,IF($M18=$J$4,$K$4,IF($M18=$J$5,$K$5,IF($M18=$J$6,$K$6,IF($M18=$J$7,$K$7)))))/12),(I18-12),0,-AB18,0),-2) -> 996500
B19: B2 | C19: Mobil | D19: =SUMIF(Process!$F$3:$F$204,Plan!B19,Process!$E$3:$E$204) -> 3572701.8 | E19: =IF(D19<1,100%,D19/K19) -> 0.028126261 | F19: Jangka Menengah (5 tahun / 2029 / 27) | G19: 45566 | H19: 46661 | I19: =(YEAR(H19)-YEAR(G19))*12+MONTH(H19)-MONTH(G19) -> 36 | J19: 100000000 | K19: =-FV($H$6/12,I19,0,J19,0) -> 1.2702371e+08 | L19: =K19/I19 -> 3528436.3 | M19: Rks. Saham | N19: =ROUND(PMT((IF(M19=$J$3,$K$3,IF(M19=$J$4,$K$4,IF(M19=$J$5,$K$5,IF(M19=$J$6,$K$6,IF(M19=$J$7,$K$7)))))/12),I19,0,-K19,0),-2) -> 2948800 | O19: =$N19/SUM($N$19:$N$22)*(O$24-(SUM(O$12:O$18))) -> 635221.85 | P19: =$N19/SUM($N$19:$N$22)*(P$24-(SUM(P$12:P$18))) -> 332107.69 | Q19: =$N19/SUM($N$19:$N$22)*(Q$24-(SUM(Q$12:Q$18))) -> 68530.158 | R19: =$N19/SUM($N$19:$N$22)*(R$24-(SUM(R$12:R$18))) -> 68530.158 | S19: =$N19/SUM($N$19:$N$22)*(S$24-(SUM(S$12:S$18))) -> 201636.81 | T19: =$N19/SUM($N$19:$N$22)*(T$24-(SUM(T$12:T$18))) -> 308385.71 | U19: =$N19/SUM($N$19:$N$22)*(U$24-(SUM(U$12:U$18))) -> 295206.84 | V19: =$N19/SUM($N$19:$N$22)*(V$24-(SUM(V$12:V$18))) -> 152874.97 | ... Z19: =$N19/SUM($N$19:$N$22)*(Z$24-(SUM(Z$12:Z$18))) -> 316293.04 | AA19: {=SUMPRODUCT(O19:Z19*(1 +(IF(M19=$J$3,$K$3,IF(M19=$J$4,$K$4,IF(M19=$J$5,$K$5,IF(M19=$J$6,$K$6,IF(M19=$J$7,$K$7)))))/12))^((COLUMN(O19:Z19) - COLUMN(O19))))} -> 4412199.6 | AB19: =K19-AA19 -> 1.2261151e+08 | AC19: =ROUND(PMT((IF($M19=$J$3,$K$3,IF($M19=$J$4,$K$4,IF($M19=$J$5,$K$5,IF($M19=$J$6,$K$6,IF($M19=$J$7,$K$7)))))/12),(I19-12),0,-AB19,0),-2) -> 4545600 | AD19: =Z19/16834 -> 18.788941
B20: C1 | C20: Menikah | D20: =SUMIF(Process!$F$3:$F$204,Plan!B20,Process!$E$3:$E$204) -> 1244611.1 | E20: =IF(D20<1,100%,D20/K20) -> 0.010193404 | F20: Jangka Panjang (10 tahun / 2034 / 32) | G20: 45566 | H20: 47392 | I20: =(YEAR(H20)-YEAR(G20))*12+MONTH(H20)-MONTH(G20) -> 60 | J20: 100000000 | K20: =-FV($H$4/12,I20,0,J20,0) -> 1.2209966e+08 | L20: =K20/I20 -> 2034994.3 | M20: Rks. Saham | N20: =ROUND(PMT((IF(M20=$J$3,$K$3,IF(M20=$J$4,$K$4,IF(M20=$J$5,$K$5,IF(M20=$J$6,$K$6,IF(M20=$J$7,$K$7)))))/12),I20,0,-K20,0),-2) -> 1495000 | O20: =$N20/SUM($N$19:$N$22)*(O$24-(SUM(O$12:O$18))) -> 322048.52 | P20: =$N20/SUM($N$19:$N$22)*(P$24-(SUM(P$12:P$18))) -> 168373.91 | Q20: =$N20/SUM($N$19:$N$22)*(Q$24-(SUM(Q$12:Q$18))) -> 34743.824 | R20: =$N20/SUM($N$19:$N$22)*(R$24-(SUM(R$12:R$18))) -> 34743.824 | S20: =$N20/SUM($N$19:$N$22)*(S$24-(SUM(S$12:S$18))) -> 102227.02 | T20: =$N20/SUM($N$19:$N$22)*(T$24-(SUM(T$12:T$18))) -> 156347.21 | U20: =$N20/SUM($N$19:$N$22)*(U$24-(SUM(U$12:U$18))) -> 149665.7 | V20: =$N20/SUM($N$19:$N$22)*(V$24-(SUM(V$12:V$18))) -> 77505.452 | ... Z20: =$N20/SUM($N$19:$N$22)*(Z$24-(SUM(Z$12:Z$18))) -> 160356.11 | AA20: {=SUMPRODUCT(O20:Z20*(1 +(IF(M20=$J$3,$K$3,IF(M20=$J$4,$K$4,IF(M20=$J$5,$K$5,IF(M20=$J$6,$K$6,IF(M20=$J$7,$K$7)))))/12))^((COLUMN(O20:Z20) - COLUMN(O20))))} -> 2236923 | AB20: =K20-AA20 -> 1.1986274e+08 | AC20: =ROUND(PMT((IF($M20=$J$3,$K$3,IF($M20=$J$4,$K$4,IF($M20=$J$5,$K$5,IF($M20=$J$6,$K$6,IF($M20=$J$7,$K$7)))))/12),(I20-12),0,-AB20,0),-2) -> 1957800 | AD20: =Z20/16834 -> 9.5257282
B21: C2 | C21: KPR Rumah | D21: =SUMIF(Process!$F$3:$F$204,Plan!B21,Process!$E$3:$E$204) -> 2062913.7 | E21: =IF(D21<1,100%,D21/K21) -> 0.010195912 | F21: Jangka Panjang (10 tahun / 2034 / 32) | G21: 45566 | H21: 47392 | I21: =(YEAR(H21)-YEAR(G21))*12+MONTH(H21)-MONTH(G21) -> 60 | J21: =150000000 -> 150000000 | K21: =-FV($H$5/12,I21,0,J21,0) -> 2.0232752e+08 | L21: =K21/I21 -> 3372125.4 | M21: Rks. Saham | N21: =ROUND(PMT((IF(M21=$J$3,$K$3,IF(M21=$J$4,$K$4,IF(M21=$J$5,$K$5,IF(M21=$J$6,$K$6,IF(M21=$J$7,$K$7)))))/12),I21,0,-K21,0),-2) -> 2477400 | O21: =$N21/SUM($N$19:$N$22)*(O$24-(SUM(O$12:O$18))) -> 533674.25 | P21: =$N21/SUM($N$19:$N$22)*(P$24-(SUM(P$12:P$18))) -> 279016.41 | Q21: =$N21/SUM($N$19:$N$22)*(Q$24-(SUM(Q$12:Q$18))) -> 57574.815 | R21: =$N21/SUM($N$19:$N$22)*(R$24-(SUM(R$12:R$18))) -> 57574.815 | S21: =$N21/SUM($N$19:$N$22)*(S$24-(SUM(S$12:S$18))) -> 169402.82 | T21: =$N21/SUM($N$19:$N$22)*(T$24-(SUM(T$12:T$18))) -> 259086.67 | U21: =$N21/SUM($N$19:$N$22)*(U$24-(SUM(U$12:U$18))) -> 248014.59 | V21: =$N21/SUM($N$19:$N$22)*(V$24-(SUM(V$12:V$18))) -> 128436.13 | ... Z21: =$N21/SUM($N$19:$N$22)*(Z$24-(SUM(Z$12:Z$18))) -> 265729.92 | AA21: {=SUMPRODUCT(O21:Z21*(1 +(IF(M21=$J$3,$K$3,IF(M21=$J$4,$K$4,IF(M21=$J$5,$K$5,IF(M21=$J$6,$K$6,IF(M21=$J$7,$K$7)))))/12))^((COLUMN(O21:Z21) - COLUMN(O21))))} -> 3706858.1 | AB21: =K21-AA21 -> 1.9862066e+08 | AC21: =ROUND(PMT((IF($M21=$J$3,$K$3,IF($M21=$J$4,$K$4,IF($M21=$J$5,$K$5,IF($M21=$J$6,$K$6,IF($M21=$J$7,$K$7)))))/12),(I21-12),0,-AB21,0),-2) -> 3244200 | AD21: =Z21/16834 -> 15.78531
B22: D1 | C22: Dana Pensiun | D22: =SUMIF(Process!$F$3:$F$204,Plan!B22,Process!$E$3:$E$204) -> 3558522.9 | E22: =IF(D22<1,100%,D22/K22) -> 0.000238655 | F22: Jangka Masa Depan (30 tahun / 2054 / 52) | G22: 45566 | H22: 56523 | I22: =(YEAR(H22)-YEAR(G22))*12+MONTH(H22)-MONTH(G22) -> 360 | J22: =100/4*(15000000*12) -> 4500000000 | K22: =-FV($H$4/12,I22,0,J22,0) -> 1.4910741e+10 | L22: =K22/I22 -> 41418725 | M22: Rks. Saham | N22: =ROUND(PMT((IF(M22=$J$3,$K$3,IF(M22=$J$4,$K$4,IF(M22=$J$5,$K$5,IF(M22=$J$6,$K$6,IF(M22=$J$7,$K$7)))))/12),I22,0,-K22,0),-2) -> 4266400 | O22: =$N22/SUM($N$19:$N$22)*(O$24-(SUM(O$12:O$18))) -> 919055.38 | P22: =$N22/SUM($N$19:$N$22)*(P$24-(SUM(P$12:P$18))) -> 480501.98 | Q22: =$N22/SUM($N$19:$N$22)*(Q$24-(SUM(Q$12:Q$18))) -> 99151.203 | R22: =$N22/SUM($N$19:$N$22)*(R$24-(SUM(R$12:R$18))) -> 99151.203 | S22: =$N22/SUM($N$19:$N$22)*(S$24-(SUM(S$12:S$18))) -> 291733.35 | T22: =$N22/SUM($N$19:$N$22)*(T$24-(SUM(T$12:T$18))) -> 446180.41 | U22: =$N22/SUM($N$19:$N$22)*(U$24-(SUM(U$12:U$18))) -> 427112.87 | V22: =$N22/SUM($N$19:$N$22)*(V$24-(SUM(V$12:V$18))) -> 221183.45 | ... Z22: =$N22/SUM($N$19:$N$22)*(Z$24-(SUM(Z$12:Z$18))) -> 457620.94 | AA22: {=SUMPRODUCT(O22:Z22*(1 +(IF(M22=$J$3,$K$3,IF(M22=$J$4,$K$4,IF(M22=$J$5,$K$5,IF(M22=$J$6,$K$6,IF(M22=$J$7,$K$7)))))/12))^((COLUMN(O22:Z22) - COLUMN(O22))))} -> 6383684.3 | AB22: =K22-AA22 -> 1.4904357e+10 | AC22: =ROUND(PMT((IF($M22=$J$3,$K$3,IF($M22=$J$4,$K$4,IF($M22=$J$5,$K$5,IF($M22=$J$6,$K$6,IF($M22=$J$7,$K$7)))))/12),(I22-12),0,-AB22,0),-2) -> 4822900 | AD22: =Z22/16834 -> 27.184326
L23: =SUM(L12:L22) -> 54072353 | N23: =SUM(N12:N22) -> 15096200 | O23: =SUM(O12:O22) -> 5800000 | P23: =SUM(P12:P22) -> 3500000 | Q23: =SUM(Q12:Q22) -> 2995000 | R23: =SUM(R12:R22) -> 2995000 | S23: =SUM(S12:S22) -> 2500000 | T23: =SUM(T12:T22) -> 2500000 | U23: =SUM(U12:U22) -> 2600000 | ... AC23: =SUM(AC12:AC22) -> 15580400 | AD23: =Z23/16834 -> 71.284306
O24: 5800000 | P24: 3500000 | Q24: 2995000 | R24: 2995000 | S24: 2500000 | T24: 2500000 | U24: 2600000 | V24: ='Emergency February'!K45 -> 2060000 | W24: ='Emergency February'!K66 -> 3600000 | X24: ='Emergency February'!K87 -> 3200000 | Y24: ='Emergency February'!K108 -> 3900000 | Z24: 1200000
R27: =4885000-5000 -> 4880000 | S27: =S19/16370 -> 12.31746 | T27: =T19/SUM($T$19:$T$22)*69.93 -> 18.431977 | Y27: =Y19/2770000*167.24 -> 44.080706 | Z27: =Z19/SUM($Z$19:$Z$22) -> 0.26357753 | AA27: =Z27*123.19 -> 32.470116
Q28: =R28-466000 -> 99373.807 | R28: =N19/SUM($N$19:$N$22)*($R$27-SUM($R$14:$R$18)) -> 565373.81 | S28: =S20/16370 -> 6.2447782 | T28: =T20/SUM($T$19:$T$22)*69.93 -> 9.3447522 | Z28: =Z20/SUM($Z$19:$Z$22) -> 0.13363009 | AA28: =Z28*123.19 -> 16.461891
Q29: =R29/(R29+R30)*767592 -> 288880.79 | R29: =N20/SUM($N$19:$N$22)*($R$27-SUM($R$14:$R$18)) -> 286636.54 | S29: =S21/16370 -> 10.34837 | T29: =T21/SUM($T$19:$T$22)*69.93 -> 15.485411 | Z29: =Z21/SUM($Z$19:$Z$22) -> 0.2214416 | AA29: =Z29*123.19 -> 27.27939
Q30: =767592-Q29 -> 478711.21 | R30: =N21/SUM($N$19:$N$22)*($R$27-SUM($R$14:$R$18)) -> 474992.22 | S30: =S22/16370 -> 17.821219 | T30: =T22/SUM($T$19:$T$22)*69.93 -> 26.66786 | Y30: =Y22/2770000*167.24 -> 63.777105 | Z30: =Z22/SUM($Z$19:$Z$22) -> 0.38135078 | AA30: =Z30*123.19 -> 46.978603
R31: =N22/SUM($N$19:$N$22)*($R$27-SUM($R$14:$R$18)) -> 817997.43

Sheet Process
D1: =SUBTOTAL(9,D3:D204) -> 20081436
B2: Period | C2: Date | D2: Nominal | E2: PV | F2: Goal | G2: Desc | H2: Product | I2: Platform | J2: Code | K2: Keterangan
B3: 45566 | C3: 45581 | D3: 880000 | E3: =-FV(Plan!$H$4/12,-((MONTH(Plan!$E$10)-MONTH(Process!B3))+((YEAR(Plan!$E$10)-YEAR(Process!B3))*12)),0,Process!D3) -> 859737.73 | F3: B1 | G3: =VLOOKUP(F3,Plan!$B$12:$C$22,2) -> Dana Darurat | H3: Rks. Pasar Uang | I3: Bibit | J3: RDPU
B4: 45566 | C4: 45581 | D4: 400000 | E4: =-FV(Plan!$H$4/12,-((MONTH(Plan!$E$10)-MONTH(Process!B4))+((YEAR(Plan!$E$10)-YEAR(Process!B4))*12)),0,Process!D4) -> 390789.88 | F4: A2 | G4: =VLOOKUP(F4,Plan!$B$12:$C$22,2) -> Balik Tegal | H4: Rks. Campuran | I4: Bibit | J4: RDCA
B5: 45566 | C5: 45581 | D5: 505000 | E5: =-FV(Plan!$H$4/12,-((MONTH(Plan!$E$10)-MONTH(Process!B5))+((YEAR(Plan!$E$10)-YEAR(Process!B5))*12)),0,Process!D5) -> 493372.22 | F5: A3 | G5: =VLOOKUP(F5,Plan!$B$12:$C$22,2) -> Wisuda (Fotografer, makeup, outfit, tiket bolak balik) | H5: Rks. Campuran | I5: Bibit | J5: RDCA
B6: 45566 | C6: 45581 | D6: 405000 | E6: =-FV(Plan!$H$4/12,-((MONTH(Plan!$E$10)-MONTH(Process!B6))+((YEAR(Plan!$E$10)-YEAR(Process!B6))*12)),0,Process!D6) -> 395674.75 | F6: A4 | G6: =VLOOKUP(F6,Plan!$B$12:$C$22,2) -> Upgrade outfit kerja | H6: Rks. Obligasi | I6: Bibit | J6: RDPT
B7: 45566 | C7: 45581 | D7: 450000 | E7: =-FV(Plan!$H$4/12,-((MONTH(Plan!$E$10)-MONTH(Process!B7))+((YEAR(Plan!$E$10)-YEAR(Process!B7))*12)),0,Process!D7) -> 439638.61 | F7: A5 | G7: =VLOOKUP(F7,Plan!$B$12:$C$22,2) -> Self Reward (Upgrade HP / Liburan) | H7: Rks. Campuran | I7: Bibit | J7: RDCA
B8: 45566 | C8: 45581 | D8: 760000 | E8: =-FV(Plan!$H$4/12,-((MONTH(Plan!$E$10)-MONTH(Process!B8))+((YEAR(Plan!$E$10)-YEAR(Process!B8))*12)),0,Process!D8) -> 742500.77 | F8: B2 | G8: =VLOOKUP(F8,Plan!$B$12:$C$22,2) -> Mobil | H8: Rks. Saham | I8: Bibit | J8: RDSA
B9: 45566 | C9: 45581 | D9: 380000 | E9: =-FV(Plan!$H$4/12,-((MONTH(Plan!$E$10)-MONTH(Process!B9))+((YEAR(Plan!$E$10)-YEAR(Process!B9))*12)),0,Process!D9) -> 371250.38 | F9: C1 | G9: =VLOOKUP(F9,Plan!$B$12:$C$22,2) -> Menikah | H9: Rks. Saham | I9: Bibit | J9: RDSA
B10: 45566 | C10: 45581 | D10: 630000 | E10: =-FV(Plan!$H$4/12,-((MONTH(Plan!$E$10)-MONTH(Process!B10))+((YEAR(Plan!$E$10)-YEAR(Process!B10))*12)),0,Process!D10) -> 615494.06 | F10: C2 | G10: =VLOOKUP(F10,Plan!$B$12:$C$22,2) -> KPR Rumah | H10: Rks. Saham | I10: Bibit | J10: RDSA
B11: 45566 | C11: 45581 | D11: 640000 | E11: =-FV(Plan!$H$4/12,-((MONTH(Plan!$E$10)-MONTH(Process!B11))+((YEAR(Plan!$E$10)-YEAR(Process!B11))*12)),0,Process!D11) -> 625263.8 | F11: D1 | G11: =VLOOKUP(F11,Plan!$B$12:$C$22,2) -> Dana Pensiun | H11: Rks. Saham | I11: Bibit | J11: RDSA
B12: 45566 | C12: 45581 | D12: 750000 | E12: =-FV(Plan!$H$4/12,-((MONTH(Plan!$E$10)-MONTH(Process!B12))+((YEAR(Plan!$E$10)-YEAR(Process!B12))*12)),0,Process!D12) -> 732731.02 | F12: A1 | G12: =VLOOKUP(F12,Plan!$B$12:$C$22,2) -> Pindahan di Jogja | H12: Tabungan | I12: Jago | J12: JAGO
B13: 45566 | C13: 45595 | D13: -750000 | E13: =-FV(Plan!$H$4/12,-((MONTH(Plan!$E$10)-MONTH(Process!B13))+((YEAR(Plan!$E$10)-YEAR(Process!B13))*12)),0,Process!D13) -> -732731.02 | F13: A1 | G13: =VLOOKUP(F13,Plan!$B$12:$C$22,2) -> Pindahan di Jogja | H13: Tabungan | I13: Jago | J13: JAGO
B14: 45597 | C14: 45598 | D14: 880000 | E14: =-FV(Plan!$H$4/12,-((MONTH(Plan!$E$10)-MONTH(Process!B14))+((YEAR(Plan!$E$10)-YEAR(Process!B14))*12)),0,Process!D14) -> 862603.52 | F14: B1 | G14: =VLOOKUP(F14,Plan!$B$12:$C$22,2) -> Dana Darurat | H14: Rks. Pasar Uang | I14: Bibit | J14: RDPU
... B17: 45597 | C17: 45598 | D17: 450000 | E17: =-FV(Plan!$H$4/12,-((MONTH(Plan!$E$10)-MONTH(Process!B17))+((YEAR(Plan!$E$10)-YEAR(Process!B17))*12)),0,Process!D17) -> 441104.07 | F17: A5 | G17: =VLOOKUP(F17,Plan!$B$12:$C$22,2) -> Self Reward (Upgrade HP / Liburan) | H17: Rks. Campuran | I17: Bibit | J17: RDCA
B18: 45597 | C18: 45611 | D18: =1260000*Plan!K20/(Plan!$K$20+Plan!$K$21) -> 474206.78 | E18: =-FV(Plan!$H$4/12,-((MONTH(Plan!$E$10)-MONTH(Process!B18))+((YEAR(Plan!$E$10)-YEAR(Process!B18))*12)),0,Process!D18) -> 464832.32 | F18: C1 | G18: =VLOOKUP(F18,Plan!$B$12:$C$22,2) -> Menikah | H18: Saham | I18: Pluang | J18: NVDA
B19: 45597 | C19: 45611 | D19: =1260000*Plan!K21/(Plan!$K$20+Plan!$K$21) -> 785793.22 | E19: =-FV(Plan!$H$4/12,-((MONTH(Plan!$E$10)-MONTH(Process!B19))+((YEAR(Plan!$E$10)-YEAR(Process!B19))*12)),0,Process!D19) -> 770259.09 | F19: C2 | G19: =VLOOKUP(F19,Plan!$B$12:$C$22,2) -> KPR Rumah | H19: Saham | I19: Pluang | J19: NVDA
B20: 45597 | C20: 45611 | D20: 5000 | E20: =-FV(Plan!$H$4/12,-((MONTH(Plan!$E$10)-MONTH(Process!B20))+((YEAR(Plan!$E$10)-YEAR(Process!B20))*12)),0,Process!D20) -> 4901.1564 | F20: D1 | G20: =VLOOKUP(F20,Plan!$B$12:$C$22,2) -> Dana Pensiun | H20: Bitcoin | I20: Pluang | J20: BTC
B21: 45597 | C21: 45623 | D21: =-D9 -> -380000 | E21: -381267 | F21: C1 | G21: =VLOOKUP(F21,Plan!$B$12:$C$22,2) -> Menikah | H21: Rks. Saham | I21: Bibit | J21: RDSA | K21: Switch to B2, D1
B22: 45597 | C22: 45623 | D22: =-202/362*D21 -> 212044.2 | E22: 212751 | F22: B2 | G22: =VLOOKUP(F22,Plan!$B$12:$C$22,2) -> Mobil | H22: Rks. Saham | I22: Bibit | J22: RDSA | K22: Switch from C1
B23: 45597 | C23: 45623 | D23: =-160/362*D21 -> 167955.8 | E23: 168516 | F23: D1 | G23: =VLOOKUP(F23,Plan!$B$12:$C$22,2) -> Dana Pensiun | H23: Rks. Saham | I23: Bibit | J23: RDSA | K23: Switch from C1
B24: 45597 | C24: 45623 | D24: =-D10 -> -630000 | E24: -632100 | F24: C2 | G24: =VLOOKUP(F24,Plan!$B$12:$C$22,2) -> KPR Rumah | H24: Rks. Saham | I24: Bibit | J24: RDSA | K24: Switch to D1
B25: 45597 | C25: 45623 | D25: =-D24 -> 630000 | E25: 632100 | F25: D1 | G25: =VLOOKUP(F25,Plan!$B$12:$C$22,2) -> Dana Pensiun | H25: Rks. Saham | I25: Bibit | J25: RDSA | K25: Switch from C2
B26: 45627 | C26: 45624 | D26: 450000 | E26: =-FV(Plan!$H$4/12,-((MONTH(Plan!$E$10)-MONTH(Process!B26))+((YEAR(Plan!$E$10)-YEAR(Process!B26))*12)),0,Process!D26) -> 442574.42 | F26: A5 | G26: =VLOOKUP(F26,Plan!$B$12:$C$22,2) -> Self Reward (Upgrade HP / Liburan) | H26: Rks. Campuran | I26: Bibit | J26: RDPC
B27: 45627 | C27: 45624 | D27: 405000 | E27: =-FV(Plan!$H$4/12,-((MONTH(Plan!$E$10)-MONTH(Process!B27))+((YEAR(Plan!$E$10)-YEAR(Process!B27))*12)),0,Process!D27) -> 398316.98 | F27: A4 | G27: =VLOOKUP(F27,Plan!$B$12:$C$22,2) -> Upgrade outfit kerja | H27: Rks. Obligasi | I27: Bibit | J27: RDPT
B28: 45627 | C28: 45624 | D28: 1000000 | E28: =-FV(Plan!$H$4/12,-((MONTH(Plan!$E$10)-MONTH(Process!B28))+((YEAR(Plan!$E$10)-YEAR(Process!B28))*12)),0,Process!D28) -> 983498.71 | F28: A3 | G28: =VLOOKUP(F28,Plan!$B$12:$C$22,2) -> Wisuda (Fotografer, makeup, outfit, tiket bolak balik) | H28: Rks. Campuran | I28: Bibit | J28: RDPC
B29: 45627 | C29: 45624 | D29: 880000 | E29: =-FV(Plan!$H$4/12,-((MONTH(Plan!$E$10)-MONTH(Process!B29))+((YEAR(Plan!$E$10)-YEAR(Process!B29))*12)),0,Process!D29) -> 865478.87 | F29: B1 | G29: =VLOOKUP(F29,Plan!$B$12:$C$22,2) -> Dana Darurat | H29: Rks. Pasar Uang | I29: Bibit | J29: RDPU
B30: 45627 | C30: 45624 | D30: 555000 | E30: =-FV(Plan!$H$4/12,-((MONTH(Plan!$E$10)-MONTH(Process!B30))+((YEAR(Plan!$E$10)-YEAR(Process!B30))*12)),0,Process!D30) -> 545841.79 | F30: B2 | G30: =VLOOKUP(F30,Plan!$B$12:$C$22,2) -> Mobil | H30: Saham | I30: Stockbit | J30: AADI
B31: 45627 | C31: 45624 | D31: =(654127+17389)*Plan!K20/(Plan!$K$20+Plan!$K$21) -> 252728.13 | E31: =-FV(Plan!$H$4/12,-((MONTH(Plan!$E$10)-MONTH(Process!B31))+((YEAR(Plan!$E$10)-YEAR(Process!B31))*12)),0,Process!D31) -> 248557.79 | F31: C1 | G31: =VLOOKUP(F31,Plan!$B$12:$C$22,2) -> Menikah | H31: Saham | I31: Pluang | J31: NVDA
B32: 45627 | C32: 45624 | D32: =(654127+17389)*Plan!K21/(Plan!$K$20+Plan!$K$21) -> 418787.87 | E32: =-FV(Plan!$H$4/12,-((MONTH(Plan!$E$10)-MONTH(Process!B32))+((YEAR(Plan!$E$10)-YEAR(Process!B32))*12)),0,Process!D32) -> 411877.33 | F32: C2 | G32: =VLOOKUP(F32,Plan!$B$12:$C$22,2) -> KPR Rumah | H32: Saham | I32: Pluang | J32: NVDA
B33: 45627 | C33: 45624 | D33: 570000 | E33: =-FV(Plan!$H$4/12,-((MONTH(Plan!$E$10)-MONTH(Process!B33))+((YEAR(Plan!$E$10)-YEAR(Process!B33))*12)),0,Process!D33) -> 560594.27 | F33: D1 | G33: =VLOOKUP(F33,Plan!$B$12:$C$22,2) -> Dana Pensiun | H33: Saham | I33: Pluang | J33: SPY
B34: 45627 | C34: 45629 | D34: -402671 | E34: =-FV(Plan!$H$4/12,-((MONTH(Plan!$E$10)-MONTH(Process!B34))+((YEAR(Plan!$E$10)-YEAR(Process!B34))*12)),0,Process!D34) -> -396026.41 | F34: A2 | G34: =VLOOKUP(F34,Plan!$B$12:$C$22,2) -> Balik Tegal | H34: Rks. Campuran | I34: Bibit | J34: RDPC | K34: Withdrawn
B35: 45658 | C35: 45659 | D35: 1000000 | E35: =-FV(Plan!$H$4/12,-((MONTH(Plan!$E$10)-MONTH(Process!B35))+((YEAR(Plan!$E$10)-YEAR(Process!B35))*12)),0,Process!D35) -> 986777.04 | F35: A3 | G35: =VLOOKUP(F35,Plan!$B$12:$C$22,2) -> Wisuda (Fotografer, makeup, outfit, tiket bolak balik) | H35: Rks. Campuran | I35: Bibit | J35: RDPC
B36: 45658 | C36: 45659 | D36: 880000 | E36: =-FV(Plan!$H$4/12,-((MONTH(Plan!$E$10)-MONTH(Process!B36))+((YEAR(Plan!$E$10)-YEAR(Process!B36))*12)),0,Process!D36) -> 868363.8 | F36: B1 | G36: =VLOOKUP(F36,Plan!$B$12:$C$22,2) -> Dana Darurat | H36: Rks. Pasar Uang | I36: Bibit | J36: RDPU
B37: 45658 | C37: 45669 | D37: 405000 | E37: =-FV(Plan!$H$4/12,-((MONTH(Plan!$E$10)-MONTH(Process!B37))+((YEAR(Plan!$E$10)-YEAR(Process!B37))*12)),0,Process!D37) -> 399644.7 | F37: A4 | G37: =VLOOKUP(F37,Plan!$B$12:$C$22,2) -> Upgrade outfit kerja | H37: Rks. Obligasi | I37: Bibit | J37: RDPT
B38: 45658 | C38: 45669 | D38: 450000 | E38: =-FV(Plan!$H$4/12,-((MONTH(Plan!$E$10)-MONTH(Process!B38))+((YEAR(Plan!$E$10)-YEAR(Process!B38))*12)),0,Process!D38) -> 444049.67 | F38: A5 | G38: =VLOOKUP(F38,Plan!$B$12:$C$22,2) -> Self Reward (Upgrade HP / Liburan) | H38: Rks. Campuran | I38: Bibit | J38: RDPC
B39: 45627 | C39: 45669 | D39: -555000 | E39: =-FV(Plan!$H$4/12,-((MONTH(Plan!$E$10)-MONTH(Process!B39))+((YEAR(Plan!$E$10)-YEAR(Process!B39))*12)),0,Process!D39) -> -545841.79 | F39: B2 | G39: =VLOOKUP(F39,Plan!$B$12:$C$22,2) -> Mobil | H39: Saham | I39: Stockbit | J39: AADI | K39: Withdrawn with profit | L39: =920194+D39 -> 365194
B40: 45658 | C40: 45669 | D40: 812000 | E40: =-FV(Plan!$H$4/12,-((MONTH(Plan!$E$10)-MONTH(Process!B40))+((YEAR(Plan!$E$10)-YEAR(Process!B40))*12)),0,Process!D40) -> 801262.96 | F40: B2 | G40: =VLOOKUP(F40,Plan!$B$12:$C$22,2) -> Mobil | H40: Saham | I40: Stockbit | J40: CBDK
B41: 45658 | C41: 45669 | D41: 345000 | E41: =-FV(Plan!$H$4/12,-((MONTH(Plan!$E$10)-MONTH(Process!B41))+((YEAR(Plan!$E$10)-YEAR(Process!B41))*12)),0,Process!D41) -> 340438.08 | F41: B2 | G41: =VLOOKUP(F41,Plan!$B$12:$C$22,2) -> Mobil | H41: Saham | I41: Stockbit | J41: RATU
B42: 45658 | C42: 45669 | D42: 824657 | E42: =-FV(Plan!$H$4/12,-((MONTH(Plan!$E$10)-MONTH(Process!B42))+((YEAR(Plan!$E$10)-YEAR(Process!B42))*12)),0,Process!D42) -> 813752.59 | F42: D1 | G42: =VLOOKUP(F42,Plan!$B$12:$C$22,2) -> Dana Pensiun | H42: Saham | I42: Pluang | J42: SPY
...

Sheet Progress
B2: Row Labels | C2: Sum of Nominal | E2: Row Labels | F2: Sum of Nominal | H2: Row Labels | I2: Sum of Nominal | K2: Row Labels | L2: Sum of Nominal
B3: Balik Tegal | C3: -2671 | E3: Bitcoin | F3: 5000 | H3: BTC | I3: 5000 | K3: Jan | L3: 5805100
B4: Dana Darurat | C4: 6160000 | E4: Rks. Campuran | F4: 3318978.9 | H4: JAGO | I4: 0 | K4: Feb | L4: 193491.28
B5: Dana Pensiun | C5: 3597080.3 | E5: Rks. Obligasi | F5: 0 | H5: NVDA | I5: 3385737.8 | K5: Mar | L5: 474000
B6: KPR Rumah | C6: 2111695.1 | E6: Rks. Pasar Uang | F6: 6160000 | H6: RDCA | I6: 2310000 | K6: Apr | L6: 1480000
B7: Menikah | C7: 1274042.7 | E7: Rks. Saham | F7: 474868.43 | H7: RDPT | I7: 0 | K7: Oct | L7: 5050000
B8: Mobil | C8: 3619639.2 | E8: Saham | F8: 10122589 | H8: RDPU | I8: 6160000 | K8: Nov | L8: 3505000
B9: Pindahan di Jogja | C9: 0 | E9: Tabungan | F9: 0 | H9: RDSA | I9: 474868.43 | K9: Dec | L9: 3573845
B10: Self Reward (Upgrade HP / Liburan) | C10: 3300000 | E10: (blank) | H10: (blank) | K10: Grand Total | L10: 20081436
B11: Upgrade outfit kerja | C11: 0 | E11: Grand Total | F11: 20081436 | H11: RDPC | I11: 1008978.9
B12: Wisuda (Fotografer, makeup, outfit, tiket bolak balik) | C12: 21649.854 | H12: AADI | I12: 0
B13: #N/A | H13: SPY | I13: 3134004.3
B14: Grand Total | C14: 20081436 | H14: CBDK | I14: 0
H15: RATU | I15: 0
H16: QQQ | I16: 3602846.8
E17: Row Labels | F17: Sum of Nominal | H17: Grand Total | I17: 20081436
E18: Bibit | F18: 9953847.3
E19: Jago | F19: 0
E20: Pluang | F20: 10127589
E21: Stockbit | F21: 0
E22: (blank)
E23: Grand Total | F23: 20081436

Sheet Inc-Exp
B2: Current | R2: Inflasi | S2: 0.06
R3: Growth Income | S3: 0.2
B4: Pendapatan | G4: Pengeluaran | M4: Balance
B5: Orang tua | C5: Mingguan | D5: 450000 | E5: 4.5 | F5: =D5*E5 -> 2025000 | G5: Makan | H5: Dasar | I5: Harian | J5: 45000 | K5: 30 | L5: =J5*K5 -> 1350000 | M5: =F5-L5 -> 675000
G6: Transportasi | H6: Dasar | I6: Mingguan | J6: 35000 | K6: 4.5 | L6: =J6*K6 -> 157500 | M6: =M5-L6 -> 517500
G7: Listrik | H7: Dasar | I7: Bulanan | J7: 150000 | K7: 1 | L7: =J7*K7 -> 150000 | M7: =M6-L7 -> 367500
G8: Laundry | H8: Dasar | I8: Mingguan | J8: 25000 | K8: 4.5 | L8: =J8*K8 -> 112500 | M8: =M7-L8 -> 255000
G9: Paket data | H9: Dasar | I9: Bulanan | J9: 75000 | K9: 1 | L9: =J9*K9 -> 75000 | M9: =M8-L9 -> 180000 | O9: Year | P9: Start | Q9: Income | S9: % | T9: Expense | U9: % | V9: Invest
G10: Perawatan diri | H10: Pribadi | I10: Bulanan | J10: 120000 | K10: 1 | L10: =J10*K10 -> 120000 | M10: =M9-L10 -> 60000 | O10: 0 | P10: 45597 | Q10: =F19 -> 6525000 | R10: =F19*4 -> 26100000 | S10: =T10/R10 -> 0.61685824 | T10: =L17*4 -> 16100000 | U10: =V10/R10 -> 0.57471264 | V10: =L18*6 -> 15000000 | W10: =V10/6 -> 2500000
G11: Potong rambut | H11: Pribadi | I11: Bulanan | J11: 40000 | K11: 1 | L11: =J11*K11 -> 40000 | M11: =M10-L11 -> 20000 | O11: 1 | P11: 45778 | Q11: =L38 -> 8500000 | R11: =L38*12 -> 102000000 | S11: =T11/R11 -> 0.52941176 | T11: =(L35+L36)*12 -> 54000000 | U11: =V11/R11 -> 0.47058824 | V11: =L37*12 -> 48000000 | W11: =V11/12 -> 4000000
G12: Vidio | H12: Hiburan | I12: Bulanan | J12: 20000 | K12: 1 | L12: =J12*K12 -> 20000 | M12: =M11-L12 -> 0 | O12: 2 | P12: 46143 | Q12: =(100%+$S$3)*(100%+($S$2-(5%*O10*$S$3)))*Q11 -> 10812000 | R12: =(100%+$S$3)*(100%+($S$2-(5%*O10*$S$3)))*R11 -> 129744000 | S12: 0.53 | T12: =S12*R12 -> 68764320 | U12: =100%-S12 -> 0.47 | V12: =U12*R12 -> 60979680 | W12: =V12/12 -> 5081640
B13: Gaji | C13: Bulanan | D13: 4500000 | E13: 1 | F13: =D13*E13 -> 4500000 | G13: Sewa Kos | H13: Dasar | I13: Bulanan | J13: 1500000 | K13: 1 | L13: =J13*K13 -> 1500000 | M13: =F13-L13 -> 3000000 | O13: 3 | P13: 46508 | Q13: =(100%+$S$3)*(100%+($S$2-(5%*O11*$S$3)))*Q12 -> 13623120 | R13: =(100%+$S$3)*(100%+($S$2-(5%*O11*$S$3)))*R12 -> 163477440 | S13: 0.53 | T13: =S13*R13 -> 86643043 | U13: =100%-S13 -> 0.47 | V13: =U13*R13 -> 76834397 | W13: =V13/12 -> 6402866.4
G14: Google Photos | H14: Hiburan | I14: Bulanan | J14: 30000 | K14: 1 | L14: =J14*K14 -> 30000 | M14: =M13-L14 -> 2970000 | O14: 4 | P14: 46874 | Q14: =(100%+$S$3)*(100%+($S$2-(5%*O12*$S$3)))*Q13 -> 17001654 | R14: =(100%+$S$3)*(100%+($S$2-(5%*O12*$S$3)))*R13 -> 2.0401985e+08 | S14: 0.53 | T14: =S14*R14 -> 1.0813052e+08 | U14: =100%-S14 -> 0.47 | V14: =U14*R14 -> 95889327 | W14: =V14/12 -> 7990777.3
G15: Jajan dan Lainnya | H15: Hiburan | I15: Mingguan | J15: 75000 | K15: 4 | L15: =J15*K15 -> 300000 | M15: =M14-L15 -> 2670000 | O15: 5 | P15: 47239 | Q15: =(100%+$S$3)*(100%+($S$2-(5%*O13*$S$3)))*Q14 -> 21014044 | R15: =(100%+$S$3)*(100%+($S$2-(5%*O13*$S$3)))*R14 -> 2.5216853e+08 | S15: 0.53 | T15: =S15*R15 -> 1.3364932e+08 | U15: =100%-S15 -> 0.47 | V15: =U15*R15 -> 1.1851921e+08 | W15: =V15/12 -> 9876600.7
G16: Dana Cadangan | H16: Dasar | I16: Bulanan | J16: 170000 | K16: 1 | L16: =J16*K16 -> 170000 | M16: =M15-L16 -> 2500000 | O16: 6 | P16: 47604 | Q16: =(100%+$S$3)*(100%+($S$2-(5%*O14*$S$3)))*Q15 -> 25721190 | R16: =(100%+$S$3)*(100%+($S$2-(5%*O14*$S$3)))*R15 -> 3.0865428e+08 | S16: 0.55 | T16: =S16*R16 -> 1.6975985e+08 | U16: =100%-S16 -> 0.45 | V16: =U16*R16 -> 1.3889443e+08 | W16: =V16/12 -> 11574535
G17: Total Kebutuhan | L17: =SUM(L5:L16) -> 4025000 | O17: 7 | P17: 47969 | Q17: =(100%+$S$3)*(100%+($S$2-(5%*O15*$S$3)))*Q16 -> 31174082 | R17: =(100%+$S$3)*(100%+($S$2-(5%*O15*$S$3)))*R16 -> 3.7408899e+08 | S17: 0.55 | T17: =S17*R17 -> 2.0574894e+08 | U17: =100%-S17 -> 0.45 | V17: =U17*R17 -> 1.6834004e+08 | W17: =V17/12 -> 14028337
G18: Invest | L18: =F19-L17 -> 2500000 | M18: =M16-L18 -> 0 | O18: 8 | P18: 48335 | Q18: =(100%+$S$3)*(100%+($S$2-(5%*O16*$S$3)))*Q17 -> 37408899 | R18: =(100%+$S$3)*(100%+($S$2-(5%*O16*$S$3)))*R17 -> 4.4890678e+08 | S18: 0.55 | T18: =S18*R18 -> 2.4689873e+08 | U18: =100%-S18 -> 0.45 | V18: =U18*R18 -> 2.0200805e+08 | W18: =V18/12 -> 16834004
B19: Total | F19: =SUM(F5:F18) -> 6525000 | G19: Total | L19: =SUM(L17+L18) -> 6525000 | M19: =L19=F19 -> TRUE | O19: 9 | P19: 48700 | Q19: =(100%+$S$3)*(100%+($S$2-(5%*O17*$S$3)))*Q18 -> 44441772 | R19: =(100%+$S$3)*(100%+($S$2-(5%*O17*$S$3)))*R18 -> 5.3330126e+08 | S19: 0.55 | T19: =S19*R19 -> 2.9331569e+08 | U19: =100%-S19 -> 0.45 | V19: =U19*R19 -> 2.3998557e+08 | W19: =V19/12 -> 19998797
O20: 10 | P20: 49065 | Q20: =(100%+$S$3)*(100%+($S$2-(5%*O18*$S$3)))*Q19 -> 52263523 | R20: =(100%+$S$3)*(100%+($S$2-(5%*O18*$S$3)))*R19 -> 6.2716228e+08 | S20: 0.55 | T20: =S20*R20 -> 3.4493925e+08 | U20: =100%-S20 -> 0.45 | V20: =U20*R20 -> 2.8222303e+08 | W20: =V20/12 -> 23518586
O21: 11 | P21: 49430 | Q21: =(100%+$S$3)*(100%+($S$2-(5%*O19*$S$3)))*Q20 -> 60834741 | R21: =(100%+$S$3)*(100%+($S$2-(5%*O19*$S$3)))*R20 -> 7.3001689e+08 | S21: 0.58 | T21: =S21*R21 -> 4.234098e+08 | U21: =100%-S21 -> 0.42 | V21: =U21*R21 -> 3.066071e+08 | W21: =V21/12 -> 25550591
B22: Estimated | O22: 12 | P22: 49796 | Q22: =(100%+$S$3)*(100%+($S$2-(5%*O20*$S$3)))*Q21 -> 70081622 | R22: =(100%+$S$3)*(100%+($S$2-(5%*O20*$S$3)))*R21 -> 8.4097946e+08 | S22: 0.58 | T22: =S22*R22 -> 4.8776809e+08 | U22: =100%-S22 -> 0.42 | V22: =U22*R22 -> 3.5321137e+08 | W22: =V22/12 -> 29434281
O23: 13 | P23: 50161 | Q23: =(100%+$S$3)*(100%+($S$2-(5%*O21*$S$3)))*Q22 -> 79893049 | R23: =(100%+$S$3)*(100%+($S$2-(5%*O21*$S$3)))*R22 -> 9.5871659e+08 | S23: 0.58 | T23: =S23*R23 -> 5.5605562e+08 | U23: =100%-S23 -> 0.42 | V23: =U23*R23 -> 4.0266097e+08 | W23: =V23/12 -> 33555081
B24: Pendapatan | G24: Pengeluaran | M24: Balance | O24: 14 | P24: 50526 | Q24: =(100%+$S$3)*(100%+($S$2-(5%*O22*$S$3)))*Q23 -> 90119359 | R24: =(100%+$S$3)*(100%+($S$2-(5%*O22*$S$3)))*R23 -> 1.0814323e+09 | S24: 0.58 | T24: =S24*R24 -> 6.2723074e+08 | U24: =100%-S24 -> 0.42 | V24: =U24*R24 -> 4.5420157e+08 | W24: =V24/12 -> 37850131
B25: Gaji | C25: Bulanan | D25: 8500000 | E25: 1 | F25: =D25*E25 -> 8500000 | G25: Makan | H25: Dasar | I25: Harian | J25: 50000 | K25: 30 | L25: =J25*K25 -> 1500000 | M25: =F25-L25 -> 7000000 | O25: 15 | P25: 50891 | Q25: =(100%+$S$3)*(100%+($S$2-(5%*O23*$S$3)))*Q24 -> 1.005732e+08 | R25: =(100%+$S$3)*(100%+($S$2-(5%*O23*$S$3)))*R24 -> 1.2068785e+09 | S25: 0.58 | T25: =S25*R25 -> 6.9998951e+08 | U25: =100%-S25 -> 0.42 | V25: =U25*R25 -> 5.0688895e+08 | W25: =V25/12 -> 42240746
G26: Transportasi | H26: Dasar | I26: Mingguan | J26: 35000 | K26: 4 | L26: =J26*K26 -> 140000 | M26: =M25-L26 -> 6860000 | O26: 16 | P26: 51257 | Q26: =(100%+$S$3)*(100%+($S$2-(5%*O24*$S$3)))*Q25 -> 1.1103282e+08 | R26: =(100%+$S$3)*(100%+($S$2-(5%*O24*$S$3)))*R25 -> 1.3323938e+09 | S26: 0.6 | T26: =S26*R26 -> 7.9943629e+08 | U26: =100%-S26 -> 0.4 | V26: =U26*R26 -> 5.3295753e+08 | W26: =V26/12 -> 44413127
G27: Laundry | H27: Dasar | I27: Mingguan | J27: 0 | K27: 4 | L27: =J27*K27 -> 0 | M27: =M26-L27 -> 6860000 | O27: 17 | P27: 51622 | Q27: =(100%+$S$3)*(100%+($S$2-(5%*O25*$S$3)))*Q26 -> 1.2124784e+08 | R27: =(100%+$S$3)*(100%+($S$2-(5%*O25*$S$3)))*R26 -> 1.454974e+09 | S27: 0.6 | T27: =S27*R27 -> 8.7298443e+08 | U27: =100%-S27 -> 0.4 | V27: =U27*R27 -> 5.8198962e+08 | W27: =V27/12 -> 48499135
G28: Paket data | H28: Dasar | I28: Bulanan | J28: 100000 | K28: 1 | L28: =J28*K28 -> 100000 | M28: =M27-L28 -> 6760000 | O28: 18 | P28: 51987 | Q28: =(100%+$S$3)*(100%+($S$2-(5%*O26*$S$3)))*Q27 -> 1.3094766e+08 | R28: =(100%+$S$3)*(100%+($S$2-(5%*O26*$S$3)))*R27 -> 1.571372e+09 | S28: 0.6 | T28: =S28*R28 -> 9.4282318e+08 | U28: =100%-S28 -> 0.4 | V28: =U28*R28 -> 6.2854879e+08 | W28: =V28/12 -> 52379066
G29: Perawatan diri | H29: Pribadi | I29: Bulanan | J29: 75000 | K29: 1 | L29: =J29*K29 -> 75000 | M29: =M28-L29 -> 6685000 | O29: 19 | P29: 52352 | Q29: =(100%+$S$3)*(100%+($S$2-(5%*O27*$S$3)))*Q28 -> 1.3985211e+08 | R29: =(100%+$S$3)*(100%+($S$2-(5%*O27*$S$3)))*R28 -> 1.6782253e+09 | S29: 0.6 | T29: =S29*R29 -> 1.0069352e+09 | U29: =100%-S29 -> 0.4 | V29: =U29*R29 -> 6.7129011e+08 | W29: =V29/12 -> 55940842
G30: Potong rambut | H30: Pribadi | I30: Bulanan | J30: 60000 | K30: 1 | L30: =J30*K30 -> 60000 | M30: =M29-L30 -> 6625000 | O30: 20 | P30: 52718 | Q30: =(100%+$S$3)*(100%+($S$2-(5%*O28*$S$3)))*Q29 -> 1.4768382e+08 | R30: =(100%+$S$3)*(100%+($S$2-(5%*O28*$S$3)))*R29 -> 1.7722059e+09 | S30: 0.6 | T30: =S30*R30 -> 1.0633235e+09 | U30: =100%-S30 -> 0.4 | V30: =U30*R30 -> 7.0888235e+08 | W30: =V30/12 -> 59073529
G31: Sewa Kos | H31: Dasar | I31: Bulanan | J31: 1600000 | K31: 1 | L31: =J31*K31 -> 1600000 | M31: =M30-L31 -> 5025000
G32: Google Photos | H32: Hiburan | I32: Bulanan | J32: 35000 | K32: 1 | L32: =J32*K32 -> 35000 | M32: =M31-L32 -> 4990000
G33: Jajan dan Lainnya | H33: Hiburan | I33: Mingguan | J33: 70000 | K33: 4 | L33: =J33*K33 -> 280000 | M33: =M32-L33 -> 4710000
G34: Dana Cadangan | H34: Dasar | I34: Bulanan | J34: 210000 | K34: 1 | L34: =J34*K34 -> 210000 | M34: =M33-L34 -> 4500000
G35: Total Kebutuhan | L35: =SUM(L25:L34) -> 4000000
G36: Transfer keluarga | L36: 500000 | M36: =M34-L36 -> 4000000
G37: Invest | L37: =M36 -> 4000000 | M37: =M36-L37 -> 0
B38: Total | F38: =SUM(F25:F37) -> 8500000 | G38: Total | L38: =L35+L36+L37 -> 8500000 | M38: =L38=F38 -> TRUE

Sheet Wisuda
A1: Item | B1: Budget | D1: Realisasi | F1: Cadangan | H1: Selisih | I1: Notes
A2: Foto | B2: 1000000 | D2: =597000+100000+285000 -> 982000 | H2: =B2-D2-F2 -> 18000
A3: Toga + Jubah | B3: 0 | D3: 0 | H3: =B3-D3-F3 -> 0
A4: PP YK JKT | B4: 600000 | D4: =270000+300000 -> 570000 | H4: =B4-D4-F4 -> 30000
A5: Sewa Jas | B5: 200000 | D5: 140000 | H5: =B5-D5-F5 -> 60000
A6: Beli Sepatu | B6: 300000 | D6: 370000 | F6: =B6-D6 -> -70000 | H6: =B6-D6-F6 -> 0
A7: Scaling gigi | B7: 250000 | D7: 350000 | F7: =B7-D7 -> -100000 | H7: =B7-D7-F7 -> 0
A8: Potong rambut | B8: 50000 | D8: 60000 | F8: =B8-D8 -> -10000 | H8: =B8-D8-F8 -> 0
A9: Hotel Jumat Sabtu | B9: 200000 | D9: 258000 | F9: =B9-D9 -> -58000 | H9: =B9-D9-F9 -> 0
A10: Cadangan | B10: 400000 | F10: =SUM(F6:F9) -> -238000 | H10: =B10+F10 -> 162000
A11: Total | B11: =SUM(B2:B10) -> 3000000 | D11: =SUM(D2:D10) -> 2730000 | H11: =SUM(H2:H10) -> 270000

Sheet Emergency February
A1: Pendapatan | F1: Pengeluaran | L1: Balance
A2: Saving | B2: Bulanan | C2: 1600000 | D2: 1 | E2: =C2*D2 -> 1600000 | F2: Makan | G2: Dasar | H2: Harian | I2: 45000 | J2: 28 | K2: =I2*J2 -> 1260000 | L2: =E2-K2 -> 340000
F3: Transportasi | G3: Dasar | H3: Mingguan | I3: 35000 | J3: 4 | K3: =I3*J3 -> 140000 | L3: =L2-K3 -> 200000
F4: Laundry | G4: Dasar | H4: Mingguan | I4: 25000 | J4: 4 | K4: =I4*J4 -> 100000 | L4: =L3-K4 -> 100000
F5: Perawatan diri | G5: Pribadi | H5: Bulanan | I5: 100000 | J5: 1 | K5: =I5*J5 -> 100000 | L5: =L4-K5 -> 0
A6: Gaji | B6: Bulanan | C6: 4500000 | D6: 1 | E6: =C6*D6 -> 4500000 | F6: Sewa Kos | G6: Dasar | H6: Bulanan | I6: 1600000 | J6: 1 | K6: =I6*J6 -> 1600000 | L6: =E6-K6 -> 2900000
F7: Google Photos | G7: Hiburan | H7: Bulanan | I7: 30000 | J7: 1 | K7: =I7*J7 -> 30000 | L7: =L6-K7 -> 2870000
F8: Jajan dan Lainnya | G8: Hiburan | H8: Mingguan | I8: 75000 | J8: 4 | K8: =I8*J8 -> 300000 | L8: =L7-K8 -> 2570000
F9: SpayLater | G9: Pribadi | H9: Bulanan | I9: 200000 | J9: 1 | K9: =I9*J9 -> 200000 | L9: =L8-K9 -> 2370000
F10: Dana Cadangan | G10: Dasar | H10: Bulanan | I10: 170000 | J10: 1 | K10: =I10*J10 -> 170000 | L10: =L9-K10 -> 2200000
F11: Total Kebutuhan | K11: =SUM(K2:K10) -> 3900000
F12: Invest | K12: =E13-K11 -> 2200000 | L12: =L10-K12 -> 0
A13: Total | E13: =SUM(E2:E12) -> 6100000 | F13: Total | K13: =SUM(K11+K12) -> 6100000 | L13: =K13=E13 -> TRUE
A15: April
A16: Pendapatan | F16: Pengeluaran | L16: Balance
A17: Gaji | B17: Bulanan | C17: 4500000 | D17: 1 | E17: =C17*D17 -> 4500000 | F17: Makan | G17: Dasar | H17: Harian | I17: 45000 | J17: 25 | K17: =I17*J17 -> 1125000
A18: THR | B18: Sekali | C18: 4500000 | D18: 1 | E18: =C18*D18 -> 4500000 | F18: Transportasi | G18: Dasar | H18: Mingguan | I18: 50000 | J18: 4 | K18: =I18*J18 -> 200000
E19: =C19*D19 -> 0 | F19: Laundry | G19: Dasar | H19: Mingguan | I19: 25000 | J19: 4 | K19: =I19*J19 -> 100000
E20: =C20*D20 -> 0 | F20: Paket data | G20: Dasar | H20: Bulanan | I20: 70000 | J20: 1 | K20: =I20*J20 -> 70000
E21: =C21*D21 -> 0 | F21: Perawatan diri | G21: Pribadi | H21: Bulanan | I21: 70000 | J21: 1 | K21: =I21*J21 -> 70000
E22: =C22*D22 -> 0 | F22: Potong rambut | G22: Pribadi | H22: Bulanan | I22: 50000 | J22: 1 | K22: =I22*J22 -> 50000
E23: =C23*D23 -> 0 | F23: Sewa Kos | G23: Dasar | H23: Bulanan | I23: 1600000 | J23: 1 | K23: =I23*J23 -> 1600000
E24: =C24*D24 -> 0 | F24: Google Photos | G24: Hiburan | H24: Bulanan | I24: 30000 | J24: 1 | K24: =I24*J24 -> 30000
E25: =C25*D25 -> 0 | F25: Jajan dan Lainnya | G25: Hiburan | H25: Mingguan | I25: 75000 | J25: 4 | K25: =I25*J25 -> 300000
E26: =C26*D26 -> 0 | F26: Total Kebutuhan | K26: =SUM(K17:K25) -> 3545000 | L26: =E30-K26 -> 5455000
E27: =C27*D27 -> 0 | F27: THR Keluarga | K27: 1200000 | L27: =L26-K27 -> 4255000
E28: =C28*D28 -> 0 | F28: Spending Lebaran | K28: 485000 | L28: =L27-K28 -> 3770000
E29: =C29*D29 -> 0 | F29: Invest | K29: =E30-(SUM(K26:K28)) -> 3770000 | L29: =L28-K29 -> 0
A30: Total | E30: =SUM(E17:E29) -> 9000000 | F30: Total | K30: =SUM(K26:K29) -> 9000000 | L30: =K30=E30 -> TRUE
A32: Mei
A33: Pendapatan | F33: Pengeluaran | L33: Balance
A34: Gaji | B34: Bulanan | C34: 3880000 | D34: 1 | E34: =C34*D34 -> 3880000 | F34: Makan | G34: Dasar | H34: Harian | I34: 50000 | J34: 30 | K34: =I34*J34 -> 1500000
A35: BSI | B35: Sekali | C35: 2000000 | D35: 1 | E35: =C35*D35 -> 2000000 | F35: Transportasi | G35: Dasar | H35: Mingguan | I35: 35000 | J35: 4 | K35: =I35*J35 -> 140000
A36: Mentoting BAK | B36: Sekali | C36: 150000 | D36: 1 | E36: =C36*D36 -> 150000 | F36: Air Minum | G36: Dasar | H36: Mingguan | I36: 22500 | J36: 4 | K36: =I36*J36 -> 90000
E37: =C37*D37 -> 0 | F37: Paket data | G37: Dasar | H37: Bulanan | I37: 100000 | J37: 1 | K37: =I37*J37 -> 100000
E38: =C38*D38 -> 0 | F38: Perawatan diri | G38: Pribadi | H38: Bulanan | I38: 75000 | J38: 1 | K38: =I38*J38 -> 75000
E39: =C39*D39 -> 0 | F39: Potong rambut | G39: Pribadi | H39: Bulanan | I39: 60000 | J39: 1 | K39: =I39*J39 -> 60000
E40: =C40*D40 -> 0 | F40: Sewa Kos | G40: Dasar | H40: Bulanan | I40: 1600000 | J40: 1 | K40: =I40*J40 -> 1600000
E41: =C41*D41 -> 0 | F41: Google Photos | G41: Hiburan | H41: Bulanan | I41: 35000 | J41: 1 | K41: =I41*J41 -> 35000
E42: =C42*D42 -> 0 | F42: Jajan dan Lainnya | G42: Hiburan | H42: Mingguan | I42: 70000 | J42: 4 | K42: =I42*J42 -> 280000
...

Sheet 2026
A1: Februari
A2: Pendapatan | F2: Pengeluaran | L2: Balance | N2: Used | O2: Balance
A3: BCA | C3: 2350000 | D3: 1 | E3: =C3*D3 -> 2350000 | F3: Makan | G3: Dasar | H3: Harian | I3: 50000 | J3: 8 | K3: =I3*J3 -> 400000 | N3: =108000+34000+26000+48000+15000+18000+34000+20000 -> 303000 | O3: =K3-N3 -> 97000
A4: Saham | C4: 830000 | D4: 1 | E4: =C4*D4 -> 830000 | F4: Transportasi | G4: Dasar | H4: Mingguan | I4: 40000 | J4: 2 | K4: =I4*J4 -> 80000 | N4: 30000 | O4: =K4-N4 -> 50000
A5: BPJS TK | C5: 4350000 | D5: 1 | E5: =C5*D5 -> 4350000 | F5: Air Minum | G5: Dasar | H5: Mingguan | I5: 10000 | J5: 2 | K5: =I5*J5 -> 20000 | N5: =35000 -> 35000 | O5: =K5-N5 -> -15000
E6: =C6*D6 -> 0 | F6: Paket data | G6: Dasar | H6: Bulanan | I6: 75000 | J6: 1 | K6: =I6*J6 -> 75000 | N6: 75000 | O6: =K6-N6 -> 0
E7: =C7*D7 -> 0 | F7: Perawatan diri | G7: Pribadi | H7: Bulanan | I7: 250000 | J7: 1 | K7: =I7*J7 -> 250000 | N7: =190000+40000+20000 -> 250000 | O7: =K7-N7 -> 0
E8: =C8*D8 -> 0 | F8: Potong rambut | G8: Pribadi | H8: Bulanan | I8: 35000 | J8: 1 | K8: =I8*J8 -> 35000 | N8: 35000 | O8: =K8-N8 -> 0
E9: =C9*D9 -> 0 | F9: Sewa Kos | G9: Dasar | H9: Bulanan | I9: 1500000 | J9: 1 | K9: =I9*J9 -> 1500000 | N9: =1300000+103000 -> 1403000 | O9: =K9-N9 -> 97000
E10: =C10*D10 -> 0 | F10: Google Photos | G10: Hiburan | H10: Bulanan | I10: 0 | J10: 1 | K10: =I10*J10 -> 0 | O10: =K10-N10 -> 0
E11: =C11*D11 -> 0 | F11: Jajan dan Lainnya | G11: Hiburan | H11: Mingguan | I11: 150000 | J11: 2 | K11: =I11*J11 -> 300000 | N11: =70000+22000+28000+47000+50000 -> 217000 | O11: =K11-N11 -> 83000
E12: =C12*D12 -> 0 | F12: Dana Cadangan | G12: Dasar | H12: Bulanan | I12: 400000 | J12: 1 | K12: =I12*J12 -> 400000 | N12: =100000+64000+20000 -> 184000 | O12: =K12-N12 -> 216000
E13: =C13*D13 -> 0 | F13: Total Kebutuhan | K13: =SUM(K3:K12) -> 3060000 | L13: =E20-K13 -> 4470000 | N13: =SUM(N3:N12) -> 2532000 | O13: =SUM(O3:O12) -> 528000
E14: 0 | F14: Paylater | K14: 270000 | L14: =L13-K14 -> 4200000 | N14: 270000 | O14: =K14-N14 -> 0
E15: 0 | F15: Persiapan OJT | K15: 1000000 | L15: =L14-K15 -> 3200000 | N15: =270000+730000 -> 1000000 | O15: =K15-N15 -> 0
E16: 0 | K16: 0 | L16: =L15-K16 -> 3200000 | O16: =K16-N16 -> 0
E17: 0 | K17: 0 | L17: =L16-K17 -> 3200000 | O17: =K17-N17 -> 0
E18: 0 | F18: Cicilan | K18: 0 | L18: =L17-K18 -> 3200000 | O18: =K18-N18 -> 0 | P18: 491000
E19: =C19*D19 -> 0 | F19: Invest | K19: =L18 -> 3200000 | L19: =L18-K19 -> 0 | N19: 3200000 | O19: =K19-N19 -> 0 | P19: 104000
A20: Total | E20: =SUM(E3:E19) -> 7530000 | F20: Total | K20: =SUM(K13:K19) -> 7530000 | L20: =K20=E20 -> TRUE | N20: =SUM(N13:N19) -> 7002000 | O20: =SUM(O13:O19) -> 528000 | P20: =SUM(P13:P19) -> 595000 | Q20: =O20-P20 -> -67000
A22: Maret
A23: Pendapatan | F23: Pengeluaran | L23: Balance | N23: Used | O23: Balance
A24: Gaji | B24: Bulanan | C24: 4400000 | D24: 1 | E24: =C24*D24 -> 4400000 | F24: Makan | G24: Dasar | H24: Harian | I24: 50000 | J24: 31 | K24: =I24*J24 -> 1550000 | O24: =K24-N24 -> 1550000
E25: =C25*D25 -> 0 | F25: Transportasi | G25: Dasar | H25: Mingguan | I25: 35000 | J25: 4 | K25: =I25*J25 -> 140000 | O25: =K25-N25 -> 140000
E26: =C26*D26 -> 0 | F26: Air Minum | G26: Dasar | H26: Mingguan | I26: 10000 | J26: 4 | K26: =I26*J26 -> 40000 | O26: =K26-N26 -> 40000
E27: =C27*D27 -> 0 | F27: Paket data | G27: Dasar | H27: Bulanan | I27: 75000 | J27: 1 | K27: =I27*J27 -> 75000 | O27: =K27-N27 -> 75000
E28: =C28*D28 -> 0 | F28: Perawatan diri | G28: Pribadi | H28: Bulanan | I28: 200000 | J28: 1 | K28: =I28*J28 -> 200000 | O28: =K28-N28 -> 200000
E29: =C29*D29 -> 0 | F29: Potong rambut | G29: Pribadi | H29: Bulanan | I29: 40000 | J29: 1 | K29: =I29*J29 -> 40000 | O29: =K29-N29 -> 40000
E30: =C30*D30 -> 0 | F30: Sewa Kos | G30: Dasar | H30: Bulanan | I30: =875000+300000 -> 1175000 | J30: 1 | K30: =I30*J30 -> 1175000 | O30: =K30-N30 -> 1175000
E31: =C31*D31 -> 0 | F31: Google Photos | G31: Hiburan | H31: Bulanan | I31: 0 | J31: 1 | K31: =I31*J31 -> 0 | O31: =K31-N31 -> 0
E32: =C32*D32 -> 0 | F32: Jajan dan Lainnya | G32: Hiburan | H32: Mingguan | I32: 75000 | J32: 4 | K32: =I32*J32 -> 300000 | O32: =K32-N32 -> 300000
E33: =C33*D33 -> 0 | F33: Dana Cadangan | G33: Dasar | H33: Bulanan | I33: 300000 | J33: 1 | K33: =I33*J33 -> 300000 | O33: =K33-N33 -> 300000
E34: =C34*D34 -> 0 | F34: Total Kebutuhan | K34: =SUM(K24:K33) -> 3820000 | L34: =E41-K34 -> 580000 | N34: =SUM(N24:N33) -> 0 | O34: =SUM(O24:O33) -> 3820000
E35: 0 | F35: Paketin ke Jakarta | K35: 80000 | L35: =L34-K35 -> 500000 | O35: =K35-N35 -> 80000
E36: 0 | F36: Batik, Sabuk, Celana Hitam | K36: 0 | L36: =L35-K36 -> 500000 | O36: =K36-N36 -> 0
E37: 0 | F37: Restricted fund | K37: 0 | L37: =L36-K37 -> 500000 | O37: =K37-N37 -> 0
E38: 0 | F38: Tiket kereta | K38: 0 | L38: =L37-K38 -> 500000 | O38: =K38-N38 -> 0
E39: 0 | F39: Cicilan | K39: 0 | L39: =L38-K39 -> 500000 | O39: =K39-N39 -> 0
E40: =C40*D40 -> 0 | F40: Invest | K40: =L39 -> 500000 | L40: =L39-K40 -> 0 | O40: =K40-N40 -> 500000
A41: Total | E41: =SUM(E24:E40) -> 4400000 | F41: Total | K41: =SUM(K34:K40) -> 4400000 | L41: =K41=E41 -> TRUE | N41: =SUM(N34:N40) -> 0 | O41: =SUM(O34:O40) -> 4400000
...
